<?xml version="1.0"?>

<robot name="Kryton_arm">
  <link name="base_link">
	<visual>
         <geometry>
          <mesh filename="package://kryton_arm/meshes/base_cylinder.stl" scale =".0001 .0001 .0001"/>
         </geometry>
         <origin xyz="0 0 0.01"/>
         <material name="black">
           <color rgba="0 1 0 1 "/>
         </material>
        </visual>
	<collision>
         <geometry>
          <mesh filename="package://kryton_arm/meshes/base_cylinder.stl" scale =".0001 .0001 .0001"/>
         </geometry>
         <origin xyz="0 0 0.01"/>
        </collision>
  </link>

  <link name="platform">
	<visual>
         <geometry>
          <mesh filename="package://kryton_arm/meshes/top_plate.stl" scale ="0.001 0.001 0.001"/>
         </geometry>
         <origin xyz="0 0 0"/>
         <material name="red">
         <color rgba="1 1 0 1 "/>
         </material>
        </visual>
	<collision>
         <geometry>
          <mesh filename="package://kryton_arm/meshes/top_plate.stl" scale ="0.001 0.001 0.001"/>
         </geometry>
         <origin xyz="0 0 0"/>
        </collision>
  </link>

  <link name="lower_arm">
	<visual>
         <geometry>
          <mesh filename="package://kryton_arm/meshes/lower_arm.stl" scale ="0.001 0.001 0.001"/>
         </geometry>
         <origin xyz="0 0 0"/>
         <material name="red"/>
        </visual>
	<collision>
         <geometry>
          <mesh filename="package://kryton_arm/meshes/lower_arm.stl" scale ="0.001 0.001 0.001"/>
         </geometry>
         <origin xyz="0 0 0"/>
        </collision>
  </link>

  <link name="top_arm">
	<visual>
         <geometry>
          <mesh filename="package://kryton_arm/meshes/top_arm.stl" scale ="0.001 0.001 0.001"/>
         </geometry>
         <origin rpy="0 1.59 0" xyz="0 0 0"/>
         <material name="red"/>
        </visual>
	<collision>
         <geometry>
          <mesh filename="package://kryton_arm/meshes/top_arm.stl" scale ="0.001 0.001 0.001"/>
         </geometry>
         <origin rpy="0 1.59 0" xyz="0 0 0"/>
        </collision>
  </link>

  <link name="wrist">
	<visual>
         <geometry>
          <mesh filename="package://kryton_arm/meshes/wrist.stl" scale ="0.001 0.001 0.001"/>
         </geometry>
         <origin rpy="0 0 0" xyz="0 0 0"/>
         <material name="black"/>
        </visual>
	<collision>
         <geometry>
          <mesh filename="package://kryton_arm/meshes/wrist.stl" scale ="0.001 0.001 0.001"/>
         </geometry>
         <origin rpy="0 0 0" xyz="0 0 0"/>
        </collision>
  </link>

  <link name="clawbase">
	<visual>
         <geometry>
          <mesh filename="package://kryton_arm/meshes/clawbase.stl" scale ="0.001 0.001 0.001"/>
         </geometry>
         <origin rpy="0 3.18 0" xyz="0 0 0"/>
         <material name="white">
           <color rgba="1 0 0 1"/>
         </material>
        </visual>
	<collision>
         <geometry>
          <mesh filename="package://kryton_arm/meshes/clawbase.stl" scale ="0.001 0.001 0.001"/>
         </geometry>
         <origin rpy="0 3.18 0" xyz="0 0 0"/>
        </collision>
  </link>

  <link name="clawr">
	<visual>
         <geometry>
          <mesh filename="package://kryton_arm/meshes/clawr.stl" scale ="0.001 0.001 0.001"/>
         </geometry>
         <origin rpy="0 0 0" xyz="0 0 0"/>
         <material name="white"/>
        </visual>
	<collision>
         <geometry>
          <mesh filename="package://kryton_arm/meshes/clawr.stl" scale ="0.001 0.001 0.001"/>
         </geometry>
         <origin rpy="0 0 0" xyz="0 0 0"/>
        </collision>
  </link>

  <link name="clawl">
	<visual>
         <geometry>
          <mesh filename="package://kryton_arm/meshes/clawl.stl" scale ="0.001 0.001 0.001"/>
         </geometry>
         <material name="white"/>
         <origin rpy="0 0 0" xyz="0 0 0"/>
        </visual>
	<collision>
         <geometry>
          <mesh filename="package://kryton_arm/meshes/clawl.stl" scale ="0.001 0.001 0.001"/>
         </geometry>
         <origin rpy="0 0 0" xyz="0 0 0"/>
        </collision>
  </link>

  <joint name="joint1" type="revolute">
    <axis xyz="0 0 1" />
    <limit effort="1000.0" lower="1.56" upper="4.68" velocity="1.0" />
    <parent link="base_link"/>
    <child link="platform"/>
    <origin rpy="0 0 1.5" xyz="0 0 0.48"/>
  </joint>

  <joint name="joint2" type="revolute">
    <axis xyz="1 0 0" />
    <limit effort="1000.0" lower="0.0" upper="3.12" velocity="1.0" />
    <parent link="platform"/>
    <child link="lower_arm"/>
    <origin xyz="0 0.19 0.28"/>
  </joint>

  <joint name="joint3" type="revolute">
    <axis xyz="1 0 0" />
    <limit effort="1000.0" lower="-1.7" upper="1.7" velocity="1.0" />
    <parent link="lower_arm"/>
    <child link="top_arm"/>
    <origin xyz="-0.25 1.0 0"/>
  </joint>

  <joint name="joint4" type="revolute">
    <axis xyz="1 0 0" />
    <limit effort="1000.0" lower="-1.7" upper="1.7" velocity="1.0" />
    <parent link="top_arm"/>
    <child link="wrist"/>
    <origin xyz="0.11 1.25 0"/>
  </joint>

  <joint name="joint5" type="revolute">
    <axis xyz="0 1 0" />
    <limit effort="1000.0" lower="-3.17" upper="0.0" velocity="1.0" />
    <parent link="wrist"/>
    <child link="clawbase"/>
    <origin xyz="0 0.63 0"/>
  </joint>

  <joint name="joint6" type="revolute">
    <axis xyz="0 0 1" />
    <limit effort="1000.0" lower="-1.4" upper="0.0" velocity="1.0" />
    <parent link="clawbase"/>
    <child link="clawr"/>
    <origin rpy="0 0 -0.31" xyz="0.11 0.34 0"/>
  </joint>

  <joint name="joint7" type="revolute">
    <axis xyz="0 0 1" />
    <limit effort="1000.0" lower="0" upper="1.4" velocity="1.0" />
    <parent link="clawbase"/>
    <child link="clawl"/>
    <origin rpy="0 0 0.22" xyz="-0.16 0.30 0"/>
    <mimic joint="joint6" multiplier="-1" offset="0" />
  </joint>

</robot>
